<?xml version="1.0" ?>
<robot name="pendulum">
  <link name="world"/>
  <joint name="world_cart" type="prismatic">
    <parent link="world"/>
    <child link="cart"/>
    <axis xyz="1 0 0"/>
    <limit effort="10.0" lower="-100.0" upper="100.0" velocity="100.0"/>
    <origin rpy="0 0 0" xyz="0 0 0"/>
  </joint>
  <link name="cart">
    <visual>
      <origin rpy="0 0 0" xyz="0 0 0"/>
      <geometry>
        <box size="0.2 0.05 0.05"/>
      </geometry>
      <material name="">
        <color rgba="0.5 0.5 0.5 1.0"/>
      </material>
    </visual>
    <inertial>
      <mass value="0.75"/>
      <inertia ixx="0.1" ixy="0.0" ixz="0.0" iyx="0.0" iyy="0.1" iyz="0.0" izx="0.0" izy="0.0" izz="0.1"/>
    </inertial>
    <collision>
      <geometry>
        <box size="0.2 0.05 0.05"/>
      </geometry>
    </collision>
  </link>
  <joint name="cart_pole" type="revolute">
    <parent link="cart"/>
    <child link="pole"/>
    <axis xyz="0 0 1"/>
    <limit effort="10.0" lower="-100.0" upper="100.0" velocity="100.0"/>
    <origin rpy="0 0 0" xyz="0 0 0"/>
  </joint>
  <link name="pole">
    <visual>
      <origin rpy="0 0 0" xyz="0 0.15 0"/>
      <geometry>
        <box size="0.02 0.3 0.02"/>
      </geometry>
      <material name="">
        <color rgba="0.5 0.5 0.5 1.0"/>
      </material>
    </visual>
    <inertial>
      <origin rpy="0 0 0" xyz="0 0.15 0"/>
      <mass value="0.025"/>
      <inertia ixx="0.1" ixy="0.0" ixz="0.0" iyx="0.0" iyy="0.1" iyz="0.0" izx="0.0" izy="0.0" izz="0.1"/>
    </inertial>
    <collision>
    <origin rpy="0 0 0" xyz="0 0.15 0"/>
      <geometry>
        <box size="0.02 0.3 0.02"/>
      </geometry>
    </collision>
  </link>
  <joint name="pole_weight" type="fixed">
    <parent link="pole"/>
    <child link="weight"/>
    <origin rpy="0 0 0" xyz="0 0.3 0"/>
  </joint>
  <link name="weight">
    <visual>
      <origin rpy="0 0 0" xyz="0 0 0"/>
      <geometry>
        <box size="0.08 0.04 0.08"/>
      </geometry>
      <material name="">
        <color rgba="0.2 0.7 0.7 1.0"/>
      </material>
    </visual>
    <inertial>
      <origin rpy="0 0 0" xyz="0 0 0"/>
      <mass value="0.3"/>
      <inertia ixx="0.1" ixy="0.0" ixz="0.0" iyx="0.0" iyy="0.1" iyz="0.0" izx="0.0" izy="0.0" izz="0.1"/>
    </inertial>
    <collision>
    <origin rpy="0 0 0" xyz="0 0 0"/>
      <geometry>
        <box size="0.08 0.04 0.08"/>
      </geometry>
    </collision>
  </link>
</robot>
